Workbook

Sheet Dashboard
A1: DATA INTELLIGENCE DASHBOARD
A2: Customer Transactions | Apr 2024 – Apr 2025 | Excel final project
A4: TOTAL REVENUE | D4: TRANSACTIONS | G4: UNITS SOLD | J4: UNIQUE CUSTOMERS
A5: 229192.47 | D5: 250 | G5: 753 | J5: 50
A7: KEY FINDINGS
A8: • Total revenue: $229,192.47 across 250 transactions.
A9: • Highest-revenue product: Laptop ($67,499.25).
A10: • Most units sold: Bookshelf (102 units).
A11: • Leading region: East ($59,288.39).
A12: • Top customer: Mark Carter ($15,659.65).
A13: • Highest-revenue category: Electronics ($171,756.05).
A15: CHARTS
A17: VISUAL SALES SUMMARY

Sheet Project Instructions
A1: PR. Final Project - "Data Intelligence Dashboard"
A2: Dataset: Use the 'Final Project Dataset' sheet containing 200+ records of customer transactions. Objective: Create a full-fledged analysis and reporting solution using Excel to analyze customer transactions, find insights, and build visualizations and dashboards. Key Topics to Implement: - Date & Time Functions: TODAY, NOW, DATEDIF, EOMONTH - FILTER Function for multi-value returns - Conditional Formatting with Icons/Arrows - Create Timestamp (using NOW and iterative calculations) - WHAT-IF Analysis: Scenario Manager, Goal Seek - Linear Regression using Data Analysis Toolpak - Data Analysis & Storytelling from the dataset - Use GroupBy concepts to find High-Value Customers using formulas - Create Dashboard using: - Pivot Tables - Pivot Charts (Bar, Line, Pie) - Slicers and Timelines - KPI Indicators with Conditional Formatting - Find most frequently purchased product or repeating names using formulas - Compare two lists and extract matching names in a new column - Create Abbreviations using TEXT functions - Build a final report with insights and storytelling Deliverable: - Well-structured workbook with multiple sheets (Raw Data, Analysis, Visualizations, Dashboard) - Summary Insights with key metrics: Total Revenue, Top Customers, Most Sold Products, Regional Sales - Use of all required formulas and functions as listed above

Sheet Raw Data
A1: Transaction_ID | B1: Date | C1: Customer_ID | D1: Customer_Name | E1: Product_ID | F1: Product_Name | G1: Category | H1: Quantity | I1: Unit_Price | J1: Payment_Method | K1: Region | L1: Customer_Segment | M1: Customer_Since | N1: Total_Amount | O1: Month | P1: Customer_Tenure_Years | Q1: Customer_Abbreviation | R1: Discounted_Amount (10%) | S1: Created_Timestamp
A2: TRX0155 | B2: 45393 | C2: CUST023 | D2: Paul Baker | E2: P009 | F2: Monitor | G2: Electronics | H2: 3 | I2: 249.99 | J2: Cash | K2: Central | L2: Basic | M2: 44425 | N2: 749.97 | O2: =TEXT(B2,"yyyy-mm") | P2: =DATEDIF(M2,TODAY(),"Y") | Q2: =UPPER(LEFT(D2,1)&MID(D2,FIND(" ",D2)+1,1)) | R2: =N2*90% | S2: =NOW()
A3: TRX0023 | B3: 45396 | C3: CUST013 | D3: Joseph Jackson | E3: P009 | F3: Monitor | G3: Electronics | H3: 3 | I3: 249.99 | J3: Credit Card | K3: Central | L3: Premium | M3: 44575 | N3: 749.97 | O3: =TEXT(B3,"yyyy-mm") | P3: =DATEDIF(M3,TODAY(),"Y") | Q3: =UPPER(LEFT(D3,1)&MID(D3,FIND(" ",D3)+1,1)) | R3: =N3*90% | S3: =NOW()
A4: TRX0139 | B4: 45399 | C4: CUST021 | D4: Kevin Scott | E4: P005 | F4: Blender | G4: Appliances | H4: 3 | I4: 59.99 | J4: PayPal | K4: South | L4: Standard | M4: 45262 | N4: 179.97 | O4: =TEXT(B4,"yyyy-mm") | P4: =DATEDIF(M4,TODAY(),"Y") | Q4: =UPPER(LEFT(D4,1)&MID(D4,FIND(" ",D4)+1,1)) | R4: =N4*90% | S4: =NOW()
A5: TRX0043 | B5: 45400 | C5: CUST046 | D5: Kathleen Bennett | E5: P005 | F5: Blender | G5: Appliances | H5: 3 | I5: 59.99 | J5: Cash | K5: North | L5: Premium | M5: 45114 | N5: 179.97 | O5: =TEXT(B5,"yyyy-mm") | P5: =DATEDIF(M5,TODAY(),"Y") | Q5: =UPPER(LEFT(D5,1)&MID(D5,FIND(" ",D5)+1,1)) | R5: =N5*90% | S5: =NOW()
A6: TRX0212 | B6: 45400 | C6: CUST003 | D6: Michael Brown | E6: P008 | F6: Bookshelf | G6: Furniture | H6: 5 | I6: 149.99 | J6: Credit Card | K6: North | L6: Premium | M6: 45295 | N6: 749.95 | O6: =TEXT(B6,"yyyy-mm") | P6: =DATEDIF(M6,TODAY(),"Y") | Q6: =UPPER(LEFT(D6,1)&MID(D6,FIND(" ",D6)+1,1)) | R6: =N6*90% | S6: =NOW()
A7: TRX0092 | B7: 45403 | C7: CUST024 | D7: Dorothy Nelson | E7: P005 | F7: Blender | G7: Appliances | H7: 2 | I7: 59.99 | J7: Cash | K7: West | L7: Standard | M7: 44746 | N7: 119.98 | O7: =TEXT(B7,"yyyy-mm") | P7: =DATEDIF(M7,TODAY(),"Y") | Q7: =UPPER(LEFT(D7,1)&MID(D7,FIND(" ",D7)+1,1)) | R7: =N7*90% | S7: =NOW()
A8: TRX0193 | B8: 45403 | C8: CUST024 | D8: Dorothy Nelson | E8: P003 | F8: Headphones | G8: Electronics | H8: 5 | I8: 149.99 | J8: Credit Card | K8: Central | L8: Standard | M8: 44418 | N8: 749.95 | O8: =TEXT(B8,"yyyy-mm") | P8: =DATEDIF(M8,TODAY(),"Y") | Q8: =UPPER(LEFT(D8,1)&MID(D8,FIND(" ",D8)+1,1)) | R8: =N8*90% | S8: =NOW()
A9: TRX0240 | B9: 45403 | C9: CUST017 | D9: Charles Allen | E9: P005 | F9: Blender | G9: Appliances | H9: 3 | I9: 59.99 | J9: Debit Card | K9: South | L9: Basic | M9: 45007 | N9: 179.97 | O9: =TEXT(B9,"yyyy-mm") | P9: =DATEDIF(M9,TODAY(),"Y") | Q9: =UPPER(LEFT(D9,1)&MID(D9,FIND(" ",D9)+1,1)) | R9: =N9*90% | S9: =NOW()
A10: TRX0135 | B10: 45405 | C10: CUST009 | D10: Robert Thomas | E10: P001 | F10: Laptop | G10: Electronics | H10: 3 | I10: 899.99 | J10: PayPal | K10: East | L10: Standard | M10: 45299 | N10: 2699.97 | O10: =TEXT(B10,"yyyy-mm") | P10: =DATEDIF(M10,TODAY(),"Y") | Q10: =UPPER(LEFT(D10,1)&MID(D10,FIND(" ",D10)+1,1)) | R10: =N10*90% | S10: =NOW()
A11: TRX0185 | B11: 45408 | C11: CUST026 | D11: Karen Hill | E11: P005 | F11: Blender | G11: Appliances | H11: 3 | I11: 59.99 | J11: Cash | K11: West | L11: Premium | M11: 45207 | N11: 179.97 | O11: =TEXT(B11,"yyyy-mm") | P11: =DATEDIF(M11,TODAY(),"Y") | Q11: =UPPER(LEFT(D11,1)&MID(D11,FIND(" ",D11)+1,1)) | R11: =N11*90% | S11: =NOW()
A12: TRX0138 | B12: 45408 | C12: CUST022 | D12: Susan Green | E12: P008 | F12: Bookshelf | G12: Furniture | H12: 1 | I12: 149.99 | J12: Credit Card | K12: West | L12: Standard | M12: 45103 | N12: 149.99 | O12: =TEXT(B12,"yyyy-mm") | P12: =DATEDIF(M12,TODAY(),"Y") | Q12: =UPPER(LEFT(D12,1)&MID(D12,FIND(" ",D12)+1,1)) | R12: =N12*90% | S12: =NOW()
A13: TRX0209 | B13: 45408 | C13: CUST046 | D13: Kathleen Bennett | E13: P008 | F13: Bookshelf | G13: Furniture | H13: 5 | I13: 149.99 | J13: Debit Card | K13: North | L13: Basic | M13: 44830 | N13: 749.95 | O13: =TEXT(B13,"yyyy-mm") | P13: =DATEDIF(M13,TODAY(),"Y") | Q13: =UPPER(LEFT(D13,1)&MID(D13,FIND(" ",D13)+1,1)) | R13: =N13*90% | S13: =NOW()
... A251: TRX0064 | B251: 45758 | C251: CUST031 | D251: Steven Turner | E251: P010 | F251: Keyboard | G251: Electronics | H251: 3 | I251: 89.99 | J251: Debit Card | K251: North | L251: Premium | M251: 44878 | N251: 269.97 | O251: =TEXT(B251,"yyyy-mm") | P251: =DATEDIF(M251,TODAY(),"Y") | Q251: =UPPER(LEFT(D251,1)&MID(D251,FIND(" ",D251)+1,1)) | R251: =N251*90% | S251: =NOW()

Sheet Analysis
A1: DATA INTELLIGENCE | ANALYSIS
A2: Formula-driven summaries based on the Raw Data transaction table. Currency is shown in USD.
A4: KEY METRICS
A5: Total Revenue | B5: =SUM('Raw Data'!$N$2:$N$251)
A6: Transactions | B6: =COUNTA('Raw Data'!$A$2:$A$251)
A7: Units Sold | B7: =SUM('Raw Data'!$H$2:$H$251)
A8: Unique Customers | B8: =SUMPRODUCT(('Raw Data'!$C$2:$C$251<>'')/COUNTIF('Raw Data'!$C$2:$C$251,'Raw Data'!$C$2:$C$251&''))
A9: Average Transaction Value | B9: =AVERAGE('Raw Data'!$N$2:$N$251)
A10: Average Unit Price | B10: =AVERAGE('Raw Data'!$I$2:$I$251)
A13: MONTHLY REVENUE TREND | E13: PRODUCT PERFORMANCE
A14: Month | B14: Revenue | C14: Transactions | E14: Product | F14: Units Sold | G14: Revenue | H14: Transactions
A15: 45383 | B15: 20919.33 | C15: 21 | E15: Blender | F15: 87 | G15: 5219.13 | H15: 29
A16: 45413 | B16: 17039.35 | C16: 19 | E16: Bookshelf | F16: 102 | G16: 15298.98 | H16: 35
A17: 45444 | B17: 19299.45 | C17: 19 | E17: Coffee Maker | F17: 39 | G17: 3119.61 | H17: 14
A18: 45474 | B18: 18479.4 | C18: 24 | E18: Desk | F18: 78 | G18: 23399.22 | H18: 26
A19: 45505 | B19: 15759.43 | C19: 18 | E19: Headphones | F19: 47 | G19: 7049.53 | H19: 16
A20: 45536 | B20: 12989.51 | C20: 19 | E20: Keyboard | F20: 89 | G20: 8009.11 | H20: 34
A21: 45566 | B21: 20609.52 | C21: 16 | E21: Laptop | F21: 75 | G21: 67499.25 | H21: 24
A22: 45597 | B22: 12309.44 | C22: 17 | E22: Monitor | F22: 88 | G22: 21999.12 | H22: 26
A23: 45627 | B23: 23039.3 | C23: 25 | E23: Office Chair | F23: 52 | G23: 10399.48 | H23: 15
A24: 45658 | B24: 25799.15 | C24: 26 | E24: Smartphone | F24: 96 | G24: 67199.04 | H24: 31
A25: 45689 | B25: 16069.38 | C25: 20
A26: 45717 | B26: 19899.38 | C26: 19
A27: 45748 | B27: 6979.83 | C27: 7
A31: REGIONAL PERFORMANCE | E31: CATEGORY PERFORMANCE | H31: TOP 10 CUSTOMERS
A32: Region | B32: Revenue | C32: Revenue Share | E32: Category | F32: Revenue | G32: Units Sold | H32: Customer ID | I32: Customer Name | J32: Revenue
A33: Central | B33: 41288.34 | C33: 0.18014702 | E33: Appliances | F33: 8338.74 | G33: 126 | H33: CUST025 | I33: Mark Carter | J33: 15659.65
A34: East | B34: 59288.39 | C34: 0.25868385 | E34: Electronics | F34: 171756.05 | G34: 395 | H34: CUST029 | I34: Edward Mitchell | J34: 11919.77
A35: North | B35: 50808.31 | C35: 0.22168403 | E35: Furniture | F35: 49097.68 | G35: 232 | H35: CUST018 | I35: Barbara Young | J35: 10649.8
A36: South | B36: 36398.75 | C36: 0.15881303 | H36: CUST012 | I36: Patricia Moore | J36: 9799.73
A37: West | B37: 41408.68 | C37: 0.18067208 | H37: CUST023 | I37: Paul Baker | J37: 8309.74
H38: CUST024 | I38: Dorothy Nelson | J38: 8269.79
H39: CUST026 | I39: Karen Hill | J39: 8009.77
H40: CUST019 | I40: Daniel King | J40: 7309.8
H41: CUST039 | I41: Lawrence Reed | J41: 6989.77
A42: CUSTOMER VALUE & FREQUENCY | H42: CUST013 | I42: Joseph Jackson | J42: 6949.84
A43: Customer ID | B43: Customer Name | C43: Transactions | D43: Units | E43: Lifetime Revenue | F43: Buyer Type
A44: CUST001 | B44: John Smith | C44: =COUNTIF('Raw Data'!$C$2:$C$251,A44) | D44: =SUMIF('Raw Data'!$C$2:$C$251,A44,'Raw Data'!$H$2:$H$251) | E44: =SUMIF('Raw Data'!$C$2:$C$251,A44,'Raw Data'!$N$2:$N$251) | F44: =IF(C44>1,"Repeat buyer","One-time buyer")
A45: CUST002 | B45: Emma Wilson | C45: =COUNTIF('Raw Data'!$C$2:$C$251,A45) | D45: =SUMIF('Raw Data'!$C$2:$C$251,A45,'Raw Data'!$H$2:$H$251) | E45: =SUMIF('Raw Data'!$C$2:$C$251,A45,'Raw Data'!$N$2:$N$251) | F45: =IF(C45>1,"Repeat buyer","One-time buyer") | H45: LIST COMPARISON
A46: CUST003 | B46: Michael Brown | C46: =COUNTIF('Raw Data'!$C$2:$C$251,A46) | D46: =SUMIF('Raw Data'!$C$2:$C$251,A46,'Raw Data'!$H$2:$H$251) | E46: =SUMIF('Raw Data'!$C$2:$C$251,A46,'Raw Data'!$N$2:$N$251) | F46: =IF(C46>1,"Repeat buyer","One-time buyer") | H46: List A name | I46: List B name | J46: Match
...

Sheet Visualizations
A1: SALES VISUALIZATIONS
A2: Corrected charts with matching data ranges. Monthly labels are formatted as dates.
A37: CHART DATA PREVIEW | F37: MONTHLY REVENUE PREVIEW
A38: Product | B38: Units Sold | C38: Revenue | F38: Month | G38: Revenue | H38: Transactions
A39: =Analysis!E15 | B39: =Analysis!F15 | C39: =Analysis!G15 | F39: =Analysis!A15 | G39: =Analysis!B15 | H39: =Analysis!C15
A40: =Analysis!E16 | B40: =Analysis!F16 | C40: =Analysis!G16 | F40: =Analysis!A16 | G40: =Analysis!B16 | H40: =Analysis!C16
A41: =Analysis!E17 | B41: =Analysis!F17 | C41: =Analysis!G17 | F41: =Analysis!A17 | G41: =Analysis!B17 | H41: =Analysis!C17
A42: =Analysis!E18 | B42: =Analysis!F18 | C42: =Analysis!G18 | F42: =Analysis!A18 | G42: =Analysis!B18 | H42: =Analysis!C18
A43: =Analysis!E19 | B43: =Analysis!F19 | C43: =Analysis!G19 | F43: =Analysis!A19 | G43: =Analysis!B19 | H43: =Analysis!C19
A44: =Analysis!E20 | B44: =Analysis!F20 | C44: =Analysis!G20 | F44: =Analysis!A20 | G44: =Analysis!B20 | H44: =Analysis!C20
A45: =Analysis!E21 | B45: =Analysis!F21 | C45: =Analysis!G21 | F45: =Analysis!A21 | G45: =Analysis!B21 | H45: =Analysis!C21
A46: =Analysis!E22 | B46: =Analysis!F22 | C46: =Analysis!G22 | F46: =Analysis!A22 | G46: =Analysis!B22 | H46: =Analysis!C22
A47: =Analysis!E23 | B47: =Analysis!F23 | C47: =Analysis!G23 | F47: =Analysis!A23 | G47: =Analysis!B23 | H47: =Analysis!C23
A48: =Analysis!E24 | B48: =Analysis!F24 | C48: =Analysis!G24 | F48: =Analysis!A24 | G48: =Analysis!B24 | H48: =Analysis!C24
F49: =Analysis!A25 | G49: =Analysis!B25 | H49: =Analysis!C25
F50: =Analysis!A26 | G50: =Analysis!B26 | H50: =Analysis!C26
F51: =Analysis!A27 | G51: =Analysis!B27 | H51: =Analysis!C27

Sheet What-If Analysis
A1: WHAT-IF ANALYSIS | DISCOUNT SCENARIOS
A3: Assumption / Metric | B3: Value | C3: Explanation
A4: Base Revenue | B4: =SUM('Raw Data'!$N$2:$N$251) | C4: Actual sales revenue from the dataset; no costs are provided.
A5: Estimated Cost Rate | B5: 0.65 | C5: Illustrative assumption only; replace with actual cost data if available.
A6: Discount Rate | B6: 0.1 | C6: Editable input; enter between 0% and 30%.
A7: Revenue After Discount | B7: =B4*(1-B6) | C7: Base revenue × (1 − discount rate).
A8: Estimated Cost | B8: =B4*B5 | C8: Cost estimate based on assumed cost rate.
A9: Estimated Profit Before Discount | B9: =B4-B8 | C9: Revenue minus estimated cost.
A10: Estimated Profit After Discount | B10: =B7-B8 | C10: Simplified estimate; assumes costs do not change with discounts.
A11: Estimated Profit Margin | B11: =IFERROR(B10/B7,0) | C11: Estimated profit after discount divided by discounted revenue.
A14: SCENARIO COMPARISON
A15: Discount Rate | B15: Revenue After Discount | C15: Estimated Profit | D15: Profit Margin
A16: 0 | B16: =$B$4*(1-A16) | C16: =B16-$B$8 | D16: =IFERROR(C16/B16,0)
A17: 0.05 | B17: =$B$4*(1-A17) | C17: =B17-$B$8 | D17: =IFERROR(C17/B17,0)
A18: DISCOUNT SCENARIO COMPARISON | B18: =$B$4*(1-A18) | C18: =B18-$B$8 | D18: =IFERROR(C18/B18,0)
A19: Discount Rate | B19: Revenue After Discount | C19: Assumed Cost (65% base revenue) | D19: Estimated Profit | E19: Estimated Margin
A20: 0 | B20: 229192.47 | C20: 148975.11 | D20: 80217.364 | E20: 0.35
A21: 0.05 | B21: 217732.85 | C21: 148975.11 | D21: 68757.741 | E21: 0.31578947
A22: 0.1 | B22: 206273.22 | C22: 148975.11 | D22: 57298.117 | E22: 0.27777778
A23: 0.15 | B23: 194813.6 | C23: 148975.11 | D23: 45838.494 | E23: 0.23529412
A24: 0.2 | B24: 183353.98 | C24: 148975.11 | D24: 34378.871 | E24: 0.1875
A25: 0.25 | B25: 171894.35 | C25: 148975.11 | D25: 22919.247 | E25: 0.13333333
A26: 0.3 | B26: 160434.73 | C26: 148975.11 | D26: 11459.623 | E26: 0.071428571
A27: Scenario Manager instructions
A28: The comparison matrix is formula-driven. To create native saved scenarios: Data → What-If Analysis → Scenario Manager → Add scenarios (e.g., 0%, 10%, 20% discount) with changing cell B6.
A29: Assumption: cost is estimated at 65% of base revenue because actual cost data is unavailable. This is an illustrative model, not actual profit.
A31: GOAL SEEK EXAMPLE
A32: Target estimated profit | B32: 45838.494
A33: Required discount rate (calculated) | B33: 0.15
A34: Interpretation | B34: With cost fixed at 65% of base revenue, the discount rate that reaches the target is calculated algebraically. For native Excel Goal Seek, set estimated profit to target by changing the discount-rate input.

Sheet Regression
A1: LINEAR REGRESSION & DESCRIPTIVE STATISTICS
A3: Regression model | B3: Revenue = Intercept + Slope × Quantity | C3: Uses transaction quantity to estimate transaction revenue.
A4: Observations | B4: =COUNT('Raw Data'!$N$2:$N$251) | C4: Number of transaction records.
A5: Intercept | B5: =INTERCEPT('Raw Data'!$N$2:$N$251,'Raw Data'!$H$2:$H$251) | C5: Estimated revenue at quantity zero; mathematical baseline.
A6: Slope | B6: =SLOPE('Raw Data'!$N$2:$N$251,'Raw Data'!$H$2:$H$251) | C6: Average change in transaction revenue per additional unit in this simple linear fit.
A7: Correlation (r) | B7: =CORREL('Raw Data'!$H$2:$H$251,'Raw Data'!$N$2:$N$251) | C7: Strength and direction of linear association.
A8: R-squared | B8: =RSQ('Raw Data'!$N$2:$N$251,'Raw Data'!$H$2:$H$251) | C8: Share of variance explained by this one-variable linear model.
A9: Mean Revenue | B9: =AVERAGE('Raw Data'!$N$2:$N$251) | C9: Average transaction revenue.
A10: Median Revenue | B10: =MEDIAN('Raw Data'!$N$2:$N$251) | C10: Middle transaction revenue.
A11: Std. Deviation | B11: =STDEV.S('Raw Data'!$N$2:$N$251) | C11: Sample standard deviation of transaction revenue.
A12: Minimum Revenue | B12: =MIN('Raw Data'!$N$2:$N$251) | C12: Smallest transaction revenue.
A13: Maximum Revenue | B13: =MAX('Raw Data'!$N$2:$N$251) | C13: Largest transaction revenue.
A15: Interpretation | B15: R-squared indicates the share of variation in transaction revenue explained by quantity in this simple linear model; it does not establish causation.
A16: FORMAL REGRESSION SUMMARY (computed from provided data)
A17: Predictor | B17: Quantity
A18: Response | B18: Total_Amount
A19: Intercept | B19: -148.85465
A20: Quantity coefficient (slope) | B20: 353.793
A21: Correlation | B21: 0.45808036
A22: R-squared | B22: 0.20983762
A23: Observations | B23: 250
A24: Interpretation | B24: R²=21.0%: quantity explains this share of variation in transaction amount in this simple linear model. Association does not imply causation; unit price also varies.

Sheet Formula Lab
A1: REQUIRED EXCEL FUNCTIONS & IMPLEMENTATION CHECKLIST
A3: Requirement | B3: Formula / Excel feature | C3: Status and notes
A4: TODAY | B4: =TODAY() | C4: Implemented in formula examples; dynamic current date.
A5: NOW / Timestamp | B5: =NOW() | C5: NOW formulas are in Raw Data; volatile, so they update on recalculation.
A6: DATEDIF | B6: =DATEDIF(M2,TODAY(),"Y") | C6: Implemented in Raw Data tenure column.
A7: EOMONTH | B7: =EOMONTH(B2,0) | C7: Used in monthly revenue analysis.
A8: FILTER | B8: =FILTER(A2:S251,K2:K251="North","No matches") | C8: Formula example for Excel 365 / Excel 2021+.
A9: Conditional Formatting | B9: Data bars + icon sets | C9: Applied to customer lifetime revenue and transaction counts in Analysis.
A10: Create fixed timestamp | B10: NOW() + iterative calculation | C10: NOW is volatile; to preserve timestamp, enable iterative calculation and use a self-referencing timestamp formula.
A11: Scenario Manager | B11: Data → What-If Analysis → Scenario Manager | C11: Scenario matrix provided; native saved scenarios must be added in desktop Excel.
A12: Goal Seek | B12: Set B10 to target profit by changing B6 | C12: Model and instructions included; execute Goal Seek in Excel for a recorded result.
A13: Linear Regression | B13: INTERCEPT, SLOPE, CORREL, RSQ | C13: Regression formulas implemented. Native ToolPak output still needs Excel Data Analysis.
A14: GroupBy / high-value customers | B14: COUNTIF / SUMIF by Customer ID | C14: Formula-driven customer table and Top 10 ranking included.
A15: PivotTables | B15: Insert → PivotTable from TransactionsTable | C15: Native PivotTables are not created in this file; instructions below.
A16: PivotCharts (bar, line, pie) | B16: Insert PivotChart from PivotTable | C16: Regular linked charts are included; create native PivotCharts in Excel if required.
A17: Slicers and timeline | B17: PivotTable Analyze → Insert Slicer / Timeline | C17: Native interactive controls require desktop Excel.
A18: Most frequently purchased product | B18: SUMIF quantity by Product | C18: Product units and revenue ranking included.
A19: Compare two lists | B19: COUNTIF list comparison | C19: Sample comparison and matching-name output included in Analysis.
A20: Abbreviations using TEXT | B20: UPPER + LEFT + MID + FIND | C20: Customer initials are calculated in Raw Data.
A21: Final report / storytelling | B21: Dashboard with linked insights | C21: Dashboard insights are formula-driven and based on the analysis tables.
A24: Native Excel feature setup guide
A25: 1. Select any cell in Raw Data → Insert → PivotTable → New Worksheet. Create PivotTables for product revenue, monthly revenue, regional sales, and customer revenue.
A26: 2. Select each PivotTable → PivotTable Analyze → PivotChart. Create bar, line, and pie charts. Add slicers for Region and Category, plus a timeline for Date; connect slicers to relevant PivotTables via Report Connections.
A27: 3. Add Scenario Manager scenarios and run Goal Seek using the What-If Analysis sheet. For strict regression requirement, enable Analysis ToolPak and run Data → Data Analysis → Regression.

Sheet Submission Checklist
A1: FINAL SUBMISSION REQUIREMENTS AUDIT
A3: Requirement | B3: Status in this workbook | C3: Evidence / limitation | D3: Final action
A4: 250+ transaction dataset | B4: Complete | C4: 250 rows retained | D4: None
A5: Date/time functions TODAY, NOW, DATEDIF, EOMONTH | B5: Included | C5: Examples are in Formula Lab / Raw Data | D5: Check formulas recalculate in Excel
A6: FILTER multi-value returns | B6: Included | C6: Dynamic FILTER formula on Pivot-Style Summaries | D6: Requires Excel 365/2021; otherwise use AutoFilter
A7: Conditional formatting with icons/arrows | B7: Partial | C7: Data bars / color scales are present; icon sets depend on the applied ranges | D7: Verify icon-set rule in Excel
A8: NOW timestamp and iterative calculation | B8: Included | C8: Timestamp field and workbook calculation settings | D8: NOW is volatile; use static timestamp if audit trail required
A9: Scenario Manager saved scenarios | B9: Incomplete | C9: Scenario comparison matrix provided; not native saved Scenario Manager scenarios | D9: Create scenarios via Data > What-If Analysis > Scenario Manager
A10: Goal Seek | B10: Partial | C10: Target and algebraic example included | D10: Run native Goal Seek in Excel and save result
A11: Linear Regression ToolPak | B11: Partial | C11: OLS statistics computed from Quantity vs Total_Amount | D11: Run Data > Data Analysis > Regression for native ToolPak output
A12: High-value customers / repeat buyers | B12: Complete | C12: Top 20 customer summary and repeat purchase insights | D12: None
A13: Dashboard KPIs and insights | B13: Complete | C13: Calculated values and data-derived insight text | D13: Check display in Excel
A14: Bar, line and pie charts | B14: Complete | C14: Six standard embedded charts | D14: Charts are regular charts, not PivotCharts
... A21: Final report with storytelling | B21: Complete | C21: Final Report includes key metrics, insights, recommendations and limitations | D21: None

Sheet Pivot-Style Summaries
A1: PIVOT-STYLE SUMMARIES & INTERACTIVE FILTERS
A2: Formula-backed summary tables calculated from the transaction data. Dropdown filters and FILTER output are provided; these are not native PivotTables or slicers.
A4: Region filter | B4: All | D4: Category filter | E4: All | G4: Metric focus | H4: Revenue
A6: PRODUCT PERFORMANCE | F6: REGIONAL PERFORMANCE
A7: Product | B7: Revenue | C7: Units Sold | D7: Transactions | F7: Region | G7: Revenue | H7: Units Sold | I7: Transactions
A8: Blender | B8: 5219.13 | C8: 87 | D8: 29 | F8: Central | G8: 41288.34 | H8: 166 | I8: 54
A9: Bookshelf | B9: 15298.98 | C9: 102 | D9: 35 | F9: East | G9: 59288.39 | H9: 161 | I9: 48
A10: Coffee Maker | B10: 3119.61 | C10: 39 | D10: 14 | F10: North | G10: 50808.31 | H10: 169 | I10: 59
A11: Desk | B11: 23399.22 | C11: 78 | D11: 26 | F11: South | G11: 36398.75 | H11: 125 | I11: 42
A12: Headphones | B12: 7049.53 | C12: 47 | D12: 16 | F12: West | G12: 41408.68 | H12: 132 | I12: 47
A13: Keyboard | B13: 8009.11 | C13: 89 | D13: 34
A14: Laptop | B14: 67499.25 | C14: 75 | D14: 24
A15: Monitor | B15: 21999.12 | C15: 88 | D15: 26
A16: Office Chair | B16: 10399.48 | C16: 52 | D16: 15
A17: Smartphone | B17: 67199.04 | C17: 96 | D17: 31
A22: MONTHLY PERFORMANCE | F22: CATEGORY PERFORMANCE
A23: Month | B23: Revenue | C23: Transactions | D23: Units Sold | F23: Category | G23: Revenue | H23: Units Sold | I23: Transactions
A24: 45383 | B24: 20919.33 | C24: 21 | D24: 67 | F24: Appliances | G24: 8338.74 | H24: 126 | I24: 43
A25: 45413 | B25: 17039.35 | C25: 19 | D25: 65 | F25: Electronics | G25: 171756.05 | H25: 395 | I25: 131
A26: 45444 | B26: 19299.45 | C26: 19 | D26: 55 | F26: Furniture | G26: 49097.68 | H26: 232 | I26: 76
A27: 45474 | B27: 18479.4 | C27: 24 | D27: 60
A28: 45505 | B28: 15759.43 | C28: 18 | D28: 57
A29: 45536 | B29: 12989.51 | C29: 19 | D29: 49
A30: 45566 | B30: 20609.52 | C30: 16 | D30: 48
A31: 45597 | B31: 12309.44 | C31: 17 | D31: 56
A32: 45627 | B32: 23039.3 | C32: 25 | D32: 70
A33: 45658 | B33: 25799.15 | C33: 26 | D33: 85
A34: 45689 | B34: 16069.38 | C34: 20 | D34: 62
A35: TOP 20 CUSTOMERS | B35: 19899.38 | C35: 19 | D35: 62 | F35: FILTERED TRANSACTIONS (Excel 365)
A36: Customer ID | B36: Customer Name | C36: Revenue | D36: Transactions | E36: Units | F36: Transaction ID | G36: Date | H36: Customer | I36: Product | J36: Category | K36: Region | L36: Revenue
A37: CUST025 | B37: Mark Carter | C37: 15659.65 | D37: 12 | E37: 35 | F37: =FILTER(CHOOSE({1,2,3,4,5,6,7},'Raw Data'!A2:A251,'Raw Data'!B2:B251,'Raw Data'!D2:D251,'Raw Data'!F2:F251,'Raw Data'!G2:G251,'Raw Data'!K2:K251,'Raw Data'!N2:N251),(IF($B$4="All",1,'Raw Data'!K2:K251=$B$4))*(IF($E$4="All",1,'Raw Data'!G2:G251=$E$4)),"No matching rows")
A38: CUST029 | B38: Edward Mitchell | C38: 11919.77 | D38: 6 | E38: 23
A39: CUST018 | B39: Barbara Young | C39: 10649.8 | D39: 5 | E39: 20
A40: CUST012 | B40: Patricia Moore | C40: 9799.73 | D40: 8 | E40: 27
A41: CUST023 | B41: Paul Baker | C41: 8309.74 | D41: 8 | E41: 26
A42: CUST024 | B42: Dorothy Nelson | C42: 8269.79 | D42: 6 | E42: 21
A43: CUST026 | B43: Karen Hill | C43: 8009.77 | D43: 8 | E43: 23
A44: CUST019 | B44: Daniel King | C44: 7309.8 | D44: 7 | E44: 20
A45: CUST039 | B45: Lawrence Reed | C45: 6989.77 | D45: 8 | E45: 23
A46: CUST013 | B46: Joseph Jackson | C46: 6949.84 | D46: 5 | E46: 16
...

Sheet Final Report
A1: FINAL REPORT — DATA INTELLIGENCE DASHBOARD
A2: Scope: 250 customer transactions from the provided dataset. Revenue means Total_Amount; no cost data was supplied, so profit is not asserted.
A4: Metric | B4: Result | C4: Interpretation
A5: Total revenue | B5: 229192.47 | C5: Sum of Total_Amount across all transactions.
A6: Transactions | B6: 250 | C6: Count of transaction records.
A7: Units sold | B7: 753 | C7: Sum of Quantity across all transactions.
A8: Average transaction value | B8: 916.76988 | C8: Total revenue divided by transaction count.
A9: Unique customers | B9: 50 | C9: Distinct Customer_ID values.
A10: Highest revenue product | B10: Laptop | C10: Generated $67,499.25 in revenue.
A11: Most frequently purchased product | B11: Bookshelf | C11: Highest total quantity: 102 units.
A12: Leading region | B12: East | C12: Generated $59,288.39 in revenue.
A13: Leading category | B13: Electronics | C13: Generated $171,756.05 in revenue.
A14: Top customer | B14: Mark Carter | C14: Customer CUST025 generated $15,659.65.
A15: Repeat customers | B15: 47 | C15: Customers with more than one transaction.
A18: STORYTELLING & RECOMMENDATIONS
A19: 1. Revenue totals $229,192.47 from 250 transactions, with an average transaction value of $916.77.
A20: 2. Laptop is the top product by revenue ($67,499.25); Bookshelf is the most frequently purchased product by units (102). These are different metrics and should not be confused.
A21: 3. East is the leading region by revenue ($59,288.39). Consider comparing regional product mix before changing inventory or marketing spend.
A22: 4. Electronics leads categories by revenue ($171,756.05). Use this as a starting point for category-level promotion analysis.
A23: 5. 47 of 50 unique customers made repeat purchases. Consider loyalty campaigns for repeat buyers and targeted re-engagement for one-time buyers.
A24: 6. Revenue is not profit: the dataset does not contain cost of goods sold, returns, or operating expenses. Any profit scenario in this workbook is explicitly assumption-based.
A25: 7. Before making operational decisions, verify the transaction date range, data quality, and whether revenue is gross or net of discounts.
